Traceback (most recent call last):
  File "/home/obm/Prog/miniconda3/envs/QisKit/lib/python3.8/site-packages/jupyter_cache/executors/utils.py", line 51, in single_nb_execution
    executenb(
  File "/home/obm/Prog/miniconda3/envs/QisKit/lib/python3.8/site-packages/nbclient/client.py", line 1204, in execute
    return NotebookClient(nb=nb, resources=resources, km=km, **kwargs).execute()
  File "/home/obm/Prog/miniconda3/envs/QisKit/lib/python3.8/site-packages/nbclient/util.py", line 84, in wrapped
    return just_run(coro(*args, **kwargs))
  File "/home/obm/Prog/miniconda3/envs/QisKit/lib/python3.8/site-packages/nbclient/util.py", line 62, in just_run
    return loop.run_until_complete(coro)
  File "/home/obm/Prog/miniconda3/envs/QisKit/lib/python3.8/asyncio/base_events.py", line 616, in run_until_complete
    return future.result()
  File "/home/obm/Prog/miniconda3/envs/QisKit/lib/python3.8/site-packages/nbclient/client.py", line 663, in async_execute
    await self.async_execute_cell(
  File "/home/obm/Prog/miniconda3/envs/QisKit/lib/python3.8/site-packages/nbclient/client.py", line 965, in async_execute_cell
    await self._check_raise_for_error(cell, cell_index, exec_reply)
  File "/home/obm/Prog/miniconda3/envs/QisKit/lib/python3.8/site-packages/nbclient/client.py", line 862, in _check_raise_for_error
    raise CellExecutionError.from_cell_and_msg(cell, exec_reply_content)
nbclient.exceptions.CellExecutionError: An error occurred while executing the following cell:
------------------
from qiskit import IBMQ,visualization
# Enter your token from the IBM cloud here for temporary activation (I have mine saved, so not necessary)
#if IBMQ.active_account() == None :
#    print("Enabling saved account")
#    IBMQ.enable_account("your token here")
### If you have used save_account beforehand, you can load it here
if (IBMQ.active_account() is None) and (IBMQ.stored_account() is not None) :
    print("Loading saved account")
    provider = IBMQ.load_account()
#
#print("Currently active account:", IBMQ.active_account())
------------------

[0;31m---------------------------------------------------------------------------[0m
[0;31mIBMQAccountCredentialsNotFound[0m            Traceback (most recent call last)
Input [0;32mIn [2][0m, in [0;36m<cell line: 7>[0;34m()[0m
[1;32m      7[0m [38;5;28;01mif[39;00m (IBMQ[38;5;241m.[39mactive_account() [38;5;129;01mis[39;00m [38;5;28;01mNone[39;00m) [38;5;129;01mand[39;00m (IBMQ[38;5;241m.[39mstored_account() [38;5;129;01mis[39;00m [38;5;129;01mnot[39;00m [38;5;28;01mNone[39;00m) :
[1;32m      8[0m     [38;5;28mprint[39m([38;5;124m"[39m[38;5;124mLoading saved account[39m[38;5;124m"[39m)
[0;32m----> 9[0m     provider [38;5;241m=[39m [43mIBMQ[49m[38;5;241;43m.[39;49m[43mload_account[49m[43m([49m[43m)[49m

File [0;32m~/Prog/miniconda3/envs/QisKit/lib/python3.8/site-packages/qiskit/providers/ibmq/ibmqfactory.py:167[0m, in [0;36mIBMQFactory.load_account[0;34m(self)[0m
[1;32m    164[0m credentials_list [38;5;241m=[39m [38;5;28mlist[39m(stored_credentials[38;5;241m.[39mvalues())
[1;32m    166[0m [38;5;28;01mif[39;00m [38;5;129;01mnot[39;00m credentials_list:
[0;32m--> 167[0m     [38;5;28;01mraise[39;00m IBMQAccountCredentialsNotFound(
[1;32m    168[0m         [38;5;124m'[39m[38;5;124mNo IBM Quantum Experience credentials found.[39m[38;5;124m'[39m)
[1;32m    170[0m [38;5;28;01mif[39;00m [38;5;28mlen[39m(credentials_list) [38;5;241m>[39m [38;5;241m1[39m:
[1;32m    171[0m     [38;5;28;01mraise[39;00m IBMQAccountMultipleCredentialsFound(
[1;32m    172[0m         [38;5;124m'[39m[38;5;124mMultiple IBM Quantum Experience credentials found. [39m[38;5;124m'[39m [38;5;241m+[39m UPDATE_ACCOUNT_TEXT)

[0;31mIBMQAccountCredentialsNotFound[0m: 'No IBM Quantum Experience credentials found.'
IBMQAccountCredentialsNotFound: 'No IBM Quantum Experience credentials found.'

