Traceback (most recent call last):
  File "/home/obm/Prog/miniconda3/envs/QisKit/lib/python3.8/site-packages/jupyter_cache/executors/utils.py", line 51, in single_nb_execution
    executenb(
  File "/home/obm/Prog/miniconda3/envs/QisKit/lib/python3.8/site-packages/nbclient/client.py", line 1204, in execute
    return NotebookClient(nb=nb, resources=resources, km=km, **kwargs).execute()
  File "/home/obm/Prog/miniconda3/envs/QisKit/lib/python3.8/site-packages/nbclient/util.py", line 84, in wrapped
    return just_run(coro(*args, **kwargs))
  File "/home/obm/Prog/miniconda3/envs/QisKit/lib/python3.8/site-packages/nbclient/util.py", line 62, in just_run
    return loop.run_until_complete(coro)
  File "/home/obm/Prog/miniconda3/envs/QisKit/lib/python3.8/asyncio/base_events.py", line 616, in run_until_complete
    return future.result()
  File "/home/obm/Prog/miniconda3/envs/QisKit/lib/python3.8/site-packages/nbclient/client.py", line 663, in async_execute
    await self.async_execute_cell(
  File "/home/obm/Prog/miniconda3/envs/QisKit/lib/python3.8/site-packages/nbclient/client.py", line 965, in async_execute_cell
    await self._check_raise_for_error(cell, cell_index, exec_reply)
  File "/home/obm/Prog/miniconda3/envs/QisKit/lib/python3.8/site-packages/nbclient/client.py", line 862, in _check_raise_for_error
    raise CellExecutionError.from_cell_and_msg(cell, exec_reply_content)
nbclient.exceptions.CellExecutionError: An error occurred while executing the following cell:
------------------
%run oracles.py 
# This command will run the file oracles.py, in which we have defined the oracle function.
------------------

[0;31m---------------------------------------------------------------------------[0m
[0;31mOSError[0m                                   Traceback (most recent call last)
File [0;32m~/Prog/miniconda3/envs/QisKit/lib/python3.8/site-packages/IPython/core/magics/execution.py:696[0m, in [0;36mExecutionMagics.run[0;34m(self, parameter_s, runner, file_finder)[0m
[1;32m    695[0m     fpath [38;5;241m=[39m arg_lst[[38;5;241m0[39m]
[0;32m--> 696[0m     filename [38;5;241m=[39m [43mfile_finder[49m[43m([49m[43mfpath[49m[43m)[49m
[1;32m    697[0m [38;5;28;01mexcept[39;00m [38;5;167;01mIndexError[39;00m [38;5;28;01mas[39;00m e:

File [0;32m~/Prog/miniconda3/envs/QisKit/lib/python3.8/site-packages/IPython/utils/path.py:91[0m, in [0;36mget_py_filename[0;34m(name)[0m
[1;32m     90[0m [38;5;28;01melse[39;00m:
[0;32m---> 91[0m     [38;5;28;01mraise[39;00m [38;5;167;01mIOError[39;00m([38;5;124m'[39m[38;5;124mFile `[39m[38;5;132;01m%r[39;00m[38;5;124m` not found.[39m[38;5;124m'[39m [38;5;241m%[39m name)

[0;31mOSError[0m: File `'oracles.py'` not found.

The above exception was the direct cause of the following exception:

[0;31mException[0m                                 Traceback (most recent call last)
Input [0;32mIn [1][0m, in [0;36m<cell line: 1>[0;34m()[0m
[0;32m----> 1[0m [43mget_ipython[49m[43m([49m[43m)[49m[38;5;241;43m.[39;49m[43mrun_line_magic[49m[43m([49m[38;5;124;43m'[39;49m[38;5;124;43mrun[39;49m[38;5;124;43m'[39;49m[43m,[49m[43m [49m[38;5;124;43m'[39;49m[38;5;124;43moracles.py[39;49m[38;5;124;43m'[39;49m[43m)[49m

File [0;32m~/Prog/miniconda3/envs/QisKit/lib/python3.8/site-packages/IPython/core/interactiveshell.py:2285[0m, in [0;36mInteractiveShell.run_line_magic[0;34m(self, magic_name, line, _stack_depth)[0m
[1;32m   2283[0m     kwargs[[38;5;124m'[39m[38;5;124mlocal_ns[39m[38;5;124m'[39m] [38;5;241m=[39m [38;5;28mself[39m[38;5;241m.[39mget_local_scope(stack_depth)
[1;32m   2284[0m [38;5;28;01mwith[39;00m [38;5;28mself[39m[38;5;241m.[39mbuiltin_trap:
[0;32m-> 2285[0m     result [38;5;241m=[39m [43mfn[49m[43m([49m[38;5;241;43m*[39;49m[43margs[49m[43m,[49m[43m [49m[38;5;241;43m*[39;49m[38;5;241;43m*[39;49m[43mkwargs[49m[43m)[49m
[1;32m   2286[0m [38;5;28;01mreturn[39;00m result

File [0;32m~/Prog/miniconda3/envs/QisKit/lib/python3.8/site-packages/IPython/core/magics/execution.py:707[0m, in [0;36mExecutionMagics.run[0;34m(self, parameter_s, runner, file_finder)[0m
[1;32m    705[0m     [38;5;28;01mif[39;00m os[38;5;241m.[39mname [38;5;241m==[39m [38;5;124m'[39m[38;5;124mnt[39m[38;5;124m'[39m [38;5;129;01mand[39;00m re[38;5;241m.[39mmatch([38;5;124mr[39m[38;5;124m"[39m[38;5;124m^[39m[38;5;124m'[39m[38;5;124m.*[39m[38;5;124m'[39m[38;5;124m$[39m[38;5;124m"[39m,fpath):
[1;32m    706[0m         warn([38;5;124m'[39m[38;5;124mFor Windows, use double quotes to wrap a filename: [39m[38;5;132;01m%r[39;00m[38;5;124mun [39m[38;5;124m"[39m[38;5;124mmypath[39m[38;5;130;01m\\[39;00m[38;5;124mmyfile.py[39m[38;5;124m"[39m[38;5;124m'[39m)
[0;32m--> 707[0m     [38;5;28;01mraise[39;00m [38;5;167;01mException[39;00m(msg) [38;5;28;01mfrom[39;00m [38;5;21;01me[39;00m
[1;32m    708[0m [38;5;28;01mexcept[39;00m [38;5;167;01mTypeError[39;00m:
[1;32m    709[0m     [38;5;28;01mif[39;00m fpath [38;5;129;01min[39;00m sys[38;5;241m.[39mmeta_path:

[0;31mException[0m: File `'oracles.py'` not found.
Exception: File `'oracles.py'` not found.

